Workbook

Sheet Roster
A1: Emp ID | B1: Name | C1: Department | D1: Role | E1: Start Date | F1: End Date | G1: Annual Salary | H1: Status
A2: E102 | B2: Employee 2 | C2: Support | D2: Lead | E2: 44256 | G2: 171000 | H2: Hired
A3: E103 | B3: Employee 3 | C3: Sales | D3: IC | E3: 43497 | G3: 207000 | H3: Hired
A4: E104 | B4: Employee 4 | C4: G&A | D4: Lead | E4: 44470 | G4: 84000 | H4: Hired
A5: E105 | B5: Employee 5 | C5: Engineering | D5: Manager | E5: 43831 | G5: 92000 | H5: Hired
A6: E106 | B6: Employee 6 | C6: Marketing | D6: IC | E6: 44593 | G6: 131000 | H6: Hired
A7: E107 | B7: Employee 7 | C7: Support | D7: Lead | E7: 45108 | G7: 85000 | H7: Hired
A8: E108 | B8: Employee 8 | C8: Sales | D8: Lead | E8: 43556 | G8: 85000 | H8: Hired
A9: E109 | B9: Employee 9 | C9: G&A | D9: IC | E9: 45108 | G9: 82000 | H9: Hired
A10: E110 | B10: Employee 10 | C10: Engineering | D10: Manager | E10: 43709 | G10: 104000 | H10: Hired
A11: E111 | B11: Employee 11 | C11: Marketing | D11: Lead | E11: 44621 | F11: 46280 | G11: 100000 | H11: Hired
A12: E112 | B12: Employee 12 | C12: Support | D12: IC | E12: 44440 | G12: 116000 | H12: Hired
A13: E113 | B13: Employee 13 | C13: Sales | D13: Manager | E13: 45200 | G13: 118000 | H13: Hired
A14: E114 | B14: Employee 14 | C14: G&A | D14: Lead | E14: 43709 | G14: 86000 | H14: Hired
A15: E115 | B15: Employee 15 | C15: Engineering | D15: Manager | E15: 43739 | G15: 122000 | H15: Hired
A16: E116 | B16: Employee 16 | C16: Marketing | D16: Manager | E16: 45536 | G16: 179000 | H16: Hired
A17: E117 | B17: Employee 17 | C17: Support | D17: Manager | E17: 44835 | G17: 186000 | H17: Hired
A18: E118 | B18: Employee 18 | C18: Sales | D18: Lead | E18: 44287 | G18: 116000 | H18: Hired
A19: E119 | B19: Employee 19 | C19: G&A | D19: Lead | E19: 45748 | G19: 90000 | H19: Hired
A20: E120 | B20: Employee 20 | C20: Engineering | D20: Manager | E20: 44440 | G20: 196000 | H20: Hired
A21: E121 | B21: Employee 21 | C21: Marketing | D21: Lead | E21: 45505 | G21: 143000 | H21: Hired
A22: E122 | B22: Employee 22 | C22: Support | D22: IC | E22: 43497 | F22: 46280 | G22: 177000 | H22: Hired
A23: E123 | B23: Employee 23 | C23: Sales | D23: Manager | E23: 45809 | G23: 108000 | H23: Hired
A24: E124 | B24: Employee 24 | C24: G&A | D24: Lead | E24: 44562 | G24: 89000 | H24: Hired
A25: E125 | B25: Employee 25 | C25: Engineering | D25: Lead | E25: 45078 | G25: 157000 | H25: Hired
A26: E126 | B26: Employee 26 | C26: Marketing | D26: Lead | E26: 44470 | G26: 197000 | H26: Hired
A27: E127 | B27: Employee 27 | C27: Support | D27: IC | E27: 45870 | G27: 87000 | H27: Hired
A28: E128 | B28: Employee 28 | C28: Sales | D28: IC | E28: 44409 | G28: 86000 | H28: Hired
A29: E129 | B29: Employee 29 | C29: G&A | D29: Lead | E29: 45627 | G29: 149000 | H29: Hired
A30: E130 | B30: Employee 30 | C30: Engineering | D30: Manager | E30: 45231 | G30: 184000 | H30: Hired
A31: E131 | B31: Employee 31 | C31: Marketing | D31: IC | E31: 45474 | G31: 158000 | H31: Hired
A32: E132 | B32: Employee 32 | C32: Support | D32: Lead | E32: 44713 | G32: 113000 | H32: Hired
A33: E133 | B33: Employee 33 | C33: Sales | D33: Manager | E33: 43678 | F33: 46157 | G33: 125000 | H33: Hired
A34: E134 | B34: Open Req 34 | C34: G&A | D34: Manager | E34: 46113 | G34: 133000 | H34: Open
A35: E135 | B35: Open Req 35 | C35: Engineering | D35: IC | E35: 46235 | G35: 197000 | H35: Open
A36: E136 | B36: Open Req 36 | C36: Marketing | D36: Manager | E36: 46113 | G36: 184000 | H36: Open
A37: E137 | B37: Open Req 37 | C37: Support | D37: IC | E37: 46296 | G37: 141000 | H37: Open
A38: E138 | B38: Open Req 38 | C38: Sales | D38: Lead | E38: 46235 | G38: 141000 | H38: Open
A39: E139 | B39: Open Req 39 | C39: G&A | D39: Lead | E39: 46235 | G39: 161000 | H39: Open
A40: E140 | B40: Open Req 40 | C40: Engineering | D40: IC | E40: 46235 | G40: 129000 | H40: Open
...

Sheet Assumptions
A1: Headcount cost assumptions
A3: Benefits load | B3: 0.22
A4: Merit increase | B4: 0.03
A5: Merit effective month | B5: 4

Sheet Monthly Cost
A1: Monthly fully-loaded cost by employee
A4: # | B4: Emp ID | C4: Department | D4: 46023 | E4: 46054 | F4: 46082 | G4: 46113 | H4: 46143 | I4: 46174 | J4: 46204 | K4: 46235 | L4: 46266 | M4: 46296 | N4: 46327 | O4: 46357 | P4: FY26
A5: 1 | B5: =INDEX(tblRoster[Emp ID],$A5) -> E102 | C5: =INDEX(tblRoster[Department],$A5) -> Support | D5: =IF(AND(INDEX(tblRoster[Start Date],$A5)<=EOMONTH(D$4,0),OR(INDEX(tblRoster[End Date],$A5)="",INDEX(tblRoster[End Date],$A5)>=D$4)),INDEX(tblRoster[Annual Salary],$A5)/12*(1+Assumptions!$B$3)*IF(MONTH(D$4)>=Assumptions!$B$5,1+Assumptions!$B$4,1),0) -> 17385 | E5: =IF(AND(INDEX(tblRoster[Start Date],$A5)<=EOMONTH(E$4,0),OR(INDEX(tblRoster[End Date],$A5)="",INDEX(tblRoster[End Date],$A5)>=E$4)),INDEX(tblRoster[Annual Salary],$A5)/12*(1+Assumptions!$B$3)*IF(MONTH(E$4)>=Assumptions!$B$5,1+Assumptions!$B$4,1),0) -> 17385 | F5: =IF(AND(INDEX(tblRoster[Start Date],$A5)<=EOMONTH(F$4,0),OR(INDEX(tblRoster[End Date],$A5)="",INDEX(tblRoster[End Date],$A5)>=F$4)),INDEX(tblRoster[Annual Salary],$A5)/12*(1+Assumptions!$B$3)*IF(MONTH(F$4)>=Assumptions!$B$5,1+Assumptions!$B$4,1),0) -> 17385 | G5: =IF(AND(INDEX(tblRoster[Start Date],$A5)<=EOMONTH(G$4,0),OR(INDEX(tblRoster[End Date],$A5)="",INDEX(tblRoster[End Date],$A5)>=G$4)),INDEX(tblRoster[Annual Salary],$A5)/12*(1+Assumptions!$B$3)*IF(MONTH(G$4)>=Assumptions!$B$5,1+Assumptions!$B$4,1),0) -> 17906.55 | H5: =IF(AND(INDEX(tblRoster[Start Date],$A5)<=EOMONTH(H$4,0),OR(INDEX(tblRoster[End Date],$A5)="",INDEX(tblRoster[End Date],$A5)>=H$4)),INDEX(tblRoster[Annual Salary],$A5)/12*(1+Assumptions!$B$3)*IF(MONTH(H$4)>=Assumptions!$B$5,1+Assumptions!$B$4,1),0) -> 17906.55 | I5: =IF(AND(INDEX(tblRoster[Start Date],$A5)<=EOMONTH(I$4,0),OR(INDEX(tblRoster[End Date],$A5)="",INDEX(tblRoster[End Date],$A5)>=I$4)),INDEX(tblRoster[Annual Salary],$A5)/12*(1+Assumptions!$B$3)*IF(MONTH(I$4)>=Assumptions!$B$5,1+Assumptions!$B$4,1),0) -> 17906.55 | J5: =IF(AND(INDEX(tblRoster[Start Date],$A5)<=EOMONTH(J$4,0),OR(INDEX(tblRoster[End Date],$A5)="",INDEX(tblRoster[End Date],$A5)>=J$4)),INDEX(tblRoster[Annual Salary],$A5)/12*(1+Assumptions!$B$3)*IF(MONTH(J$4)>=Assumptions!$B$5,1+Assumptions!$B$4,1),0) -> 17906.55 | K5: =IF(AND(INDEX(tblRoster[Start Date],$A5)<=EOMONTH(K$4,0),OR(INDEX(tblRoster[End Date],$A5)="",INDEX(tblRoster[End Date],$A5)>=K$4)),INDEX(tblRoster[Annual Salary],$A5)/12*(1+Assumptions!$B$3)*IF(MONTH(K$4)>=Assumptions!$B$5,1+Assumptions!$B$4,1),0) -> 17906.55 | ... O5: =IF(AND(INDEX(tblRoster[Start Date],$A5)<=EOMONTH(O$4,0),OR(INDEX(tblRoster[End Date],$A5)="",INDEX(tblRoster[End Date],$A5)>=O$4)),INDEX(tblRoster[Annual Salary],$A5)/12*(1+Assumptions!$B$3)*IF(MONTH(O$4)>=Assumptions!$B$5,1+Assumptions!$B$4,1),0) -> 17906.55 | P5: =SUM(D5:O5) -> 213313.95
A6: 2 | B6: =INDEX(tblRoster[Emp ID],$A6) -> E103 | C6: =INDEX(tblRoster[Department],$A6) -> Sales | D6: =IF(AND(INDEX(tblRoster[Start Date],$A6)<=EOMONTH(D$4,0),OR(INDEX(tblRoster[End Date],$A6)="",INDEX(tblRoster[End Date],$A6)>=D$4)),INDEX(tblRoster[Annual Salary],$A6)/12*(1+Assumptions!$B$3)*IF(MONTH(D$4)>=Assumptions!$B$5,1+Assumptions!$B$4,1),0) -> 21045 | E6: =IF(AND(INDEX(tblRoster[Start Date],$A6)<=EOMONTH(E$4,0),OR(INDEX(tblRoster[End Date],$A6)="",INDEX(tblRoster[End Date],$A6)>=E$4)),INDEX(tblRoster[Annual Salary],$A6)/12*(1+Assumptions!$B$3)*IF(MONTH(E$4)>=Assumptions!$B$5,1+Assumptions!$B$4,1),0) -> 21045 | F6: =IF(AND(INDEX(tblRoster[Start Date],$A6)<=EOMONTH(F$4,0),OR(INDEX(tblRoster[End Date],$A6)="",INDEX(tblRoster[End Date],$A6)>=F$4)),INDEX(tblRoster[Annual Salary],$A6)/12*(1+Assumptions!$B$3)*IF(MONTH(F$4)>=Assumptions!$B$5,1+Assumptions!$B$4,1),0) -> 21045 | G6: =IF(AND(INDEX(tblRoster[Start Date],$A6)<=EOMONTH(G$4,0),OR(INDEX(tblRoster[End Date],$A6)="",INDEX(tblRoster[End Date],$A6)>=G$4)),INDEX(tblRoster[Annual Salary],$A6)/12*(1+Assumptions!$B$3)*IF(MONTH(G$4)>=Assumptions!$B$5,1+Assumptions!$B$4,1),0) -> 21676.35 | H6: =IF(AND(INDEX(tblRoster[Start Date],$A6)<=EOMONTH(H$4,0),OR(INDEX(tblRoster[End Date],$A6)="",INDEX(tblRoster[End Date],$A6)>=H$4)),INDEX(tblRoster[Annual Salary],$A6)/12*(1+Assumptions!$B$3)*IF(MONTH(H$4)>=Assumptions!$B$5,1+Assumptions!$B$4,1),0) -> 21676.35 | I6: =IF(AND(INDEX(tblRoster[Start Date],$A6)<=EOMONTH(I$4,0),OR(INDEX(tblRoster[End Date],$A6)="",INDEX(tblRoster[End Date],$A6)>=I$4)),INDEX(tblRoster[Annual Salary],$A6)/12*(1+Assumptions!$B$3)*IF(MONTH(I$4)>=Assumptions!$B$5,1+Assumptions!$B$4,1),0) -> 21676.35 | J6: =IF(AND(INDEX(tblRoster[Start Date],$A6)<=EOMONTH(J$4,0),OR(INDEX(tblRoster[End Date],$A6)="",INDEX(tblRoster[End Date],$A6)>=J$4)),INDEX(tblRoster[Annual Salary],$A6)/12*(1+Assumptions!$B$3)*IF(MONTH(J$4)>=Assumptions!$B$5,1+Assumptions!$B$4,1),0) -> 21676.35 | K6: =IF(AND(INDEX(tblRoster[Start Date],$A6)<=EOMONTH(K$4,0),OR(INDEX(tblRoster[End Date],$A6)="",INDEX(tblRoster[End Date],$A6)>=K$4)),INDEX(tblRoster[Annual Salary],$A6)/12*(1+Assumptions!$B$3)*IF(MONTH(K$4)>=Assumptions!$B$5,1+Assumptions!$B$4,1),0) -> 21676.35 | ... O6: =IF(AND(INDEX(tblRoster[Start Date],$A6)<=EOMONTH(O$4,0),OR(INDEX(tblRoster[End Date],$A6)="",INDEX(tblRoster[End Date],$A6)>=O$4)),INDEX(tblRoster[Annual Salary],$A6)/12*(1+Assumptions!$B$3)*IF(MONTH(O$4)>=Assumptions!$B$5,1+Assumptions!$B$4,1),0) -> 21676.35 | P6: =SUM(D6:O6) -> 258222.15
A7: 3 | B7: =INDEX(tblRoster[Emp ID],$A7) -> E104 | C7: =INDEX(tblRoster[Department],$A7) -> G&A | D7: =IF(AND(INDEX(tblRoster[Start Date],$A7)<=EOMONTH(D$4,0),OR(INDEX(tblRoster[End Date],$A7)="",INDEX(tblRoster[End Date],$A7)>=D$4)),INDEX(tblRoster[Annual Salary],$A7)/12*(1+Assumptions!$B$3)*IF(MONTH(D$4)>=Assumptions!$B$5,1+Assumptions!$B$4,1),0) -> 8540 | E7: =IF(AND(INDEX(tblRoster[Start Date],$A7)<=EOMONTH(E$4,0),OR(INDEX(tblRoster[End Date],$A7)="",INDEX(tblRoster[End Date],$A7)>=E$4)),INDEX(tblRoster[Annual Salary],$A7)/12*(1+Assumptions!$B$3)*IF(MONTH(E$4)>=Assumptions!$B$5,1+Assumptions!$B$4,1),0) -> 8540 | F7: =IF(AND(INDEX(tblRoster[Start Date],$A7)<=EOMONTH(F$4,0),OR(INDEX(tblRoster[End Date],$A7)="",INDEX(tblRoster[End Date],$A7)>=F$4)),INDEX(tblRoster[Annual Salary],$A7)/12*(1+Assumptions!$B$3)*IF(MONTH(F$4)>=Assumptions!$B$5,1+Assumptions!$B$4,1),0) -> 8540 | G7: =IF(AND(INDEX(tblRoster[Start Date],$A7)<=EOMONTH(G$4,0),OR(INDEX(tblRoster[End Date],$A7)="",INDEX(tblRoster[End Date],$A7)>=G$4)),INDEX(tblRoster[Annual Salary],$A7)/12*(1+Assumptions!$B$3)*IF(MONTH(G$4)>=Assumptions!$B$5,1+Assumptions!$B$4,1),0) -> 8796.2 | H7: =IF(AND(INDEX(tblRoster[Start Date],$A7)<=EOMONTH(H$4,0),OR(INDEX(tblRoster[End Date],$A7)="",INDEX(tblRoster[End Date],$A7)>=H$4)),INDEX(tblRoster[Annual Salary],$A7)/12*(1+Assumptions!$B$3)*IF(MONTH(H$4)>=Assumptions!$B$5,1+Assumptions!$B$4,1),0) -> 8796.2 | I7: =IF(AND(INDEX(tblRoster[Start Date],$A7)<=EOMONTH(I$4,0),OR(INDEX(tblRoster[End Date],$A7)="",INDEX(tblRoster[End Date],$A7)>=I$4)),INDEX(tblRoster[Annual Salary],$A7)/12*(1+Assumptions!$B$3)*IF(MONTH(I$4)>=Assumptions!$B$5,1+Assumptions!$B$4,1),0) -> 8796.2 | J7: =IF(AND(INDEX(tblRoster[Start Date],$A7)<=EOMONTH(J$4,0),OR(INDEX(tblRoster[End Date],$A7)="",INDEX(tblRoster[End Date],$A7)>=J$4)),INDEX(tblRoster[Annual Salary],$A7)/12*(1+Assumptions!$B$3)*IF(MONTH(J$4)>=Assumptions!$B$5,1+Assumptions!$B$4,1),0) -> 8796.2 | K7: =IF(AND(INDEX(tblRoster[Start Date],$A7)<=EOMONTH(K$4,0),OR(INDEX(tblRoster[End Date],$A7)="",INDEX(tblRoster[End Date],$A7)>=K$4)),INDEX(tblRoster[Annual Salary],$A7)/12*(1+Assumptions!$B$3)*IF(MONTH(K$4)>=Assumptions!$B$5,1+Assumptions!$B$4,1),0) -> 8796.2 | ... O7: =IF(AND(INDEX(tblRoster[Start Date],$A7)<=EOMONTH(O$4,0),OR(INDEX(tblRoster[End Date],$A7)="",INDEX(tblRoster[End Date],$A7)>=O$4)),INDEX(tblRoster[Annual Salary],$A7)/12*(1+Assumptions!$B$3)*IF(MONTH(O$4)>=Assumptions!$B$5,1+Assumptions!$B$4,1),0) -> 8796.2 | P7: =SUM(D7:O7) -> 104785.8
A8: 4 | B8: =INDEX(tblRoster[Emp ID],$A8) -> E105 | C8: =INDEX(tblRoster[Department],$A8) -> Engineering | D8: =IF(AND(INDEX(tblRoster[Start Date],$A8)<=EOMONTH(D$4,0),OR(INDEX(tblRoster[End Date],$A8)="",INDEX(tblRoster[End Date],$A8)>=D$4)),INDEX(tblRoster[Annual Salary],$A8)/12*(1+Assumptions!$B$3)*IF(MONTH(D$4)>=Assumptions!$B$5,1+Assumptions!$B$4,1),0) -> 9353.3333 | E8: =IF(AND(INDEX(tblRoster[Start Date],$A8)<=EOMONTH(E$4,0),OR(INDEX(tblRoster[End Date],$A8)="",INDEX(tblRoster[End Date],$A8)>=E$4)),INDEX(tblRoster[Annual Salary],$A8)/12*(1+Assumptions!$B$3)*IF(MONTH(E$4)>=Assumptions!$B$5,1+Assumptions!$B$4,1),0) -> 9353.3333 | F8: =IF(AND(INDEX(tblRoster[Start Date],$A8)<=EOMONTH(F$4,0),OR(INDEX(tblRoster[End Date],$A8)="",INDEX(tblRoster[End Date],$A8)>=F$4)),INDEX(tblRoster[Annual Salary],$A8)/12*(1+Assumptions!$B$3)*IF(MONTH(F$4)>=Assumptions!$B$5,1+Assumptions!$B$4,1),0) -> 9353.3333 | G8: =IF(AND(INDEX(tblRoster[Start Date],$A8)<=EOMONTH(G$4,0),OR(INDEX(tblRoster[End Date],$A8)="",INDEX(tblRoster[End Date],$A8)>=G$4)),INDEX(tblRoster[Annual Salary],$A8)/12*(1+Assumptions!$B$3)*IF(MONTH(G$4)>=Assumptions!$B$5,1+Assumptions!$B$4,1),0) -> 9633.9333 | H8: =IF(AND(INDEX(tblRoster[Start Date],$A8)<=EOMONTH(H$4,0),OR(INDEX(tblRoster[End Date],$A8)="",INDEX(tblRoster[End Date],$A8)>=H$4)),INDEX(tblRoster[Annual Salary],$A8)/12*(1+Assumptions!$B$3)*IF(MONTH(H$4)>=Assumptions!$B$5,1+Assumptions!$B$4,1),0) -> 9633.9333 | I8: =IF(AND(INDEX(tblRoster[Start Date],$A8)<=EOMONTH(I$4,0),OR(INDEX(tblRoster[End Date],$A8)="",INDEX(tblRoster[End Date],$A8)>=I$4)),INDEX(tblRoster[Annual Salary],$A8)/12*(1+Assumptions!$B$3)*IF(MONTH(I$4)>=Assumptions!$B$5,1+Assumptions!$B$4,1),0) -> 9633.9333 | J8: =IF(AND(INDEX(tblRoster[Start Date],$A8)<=EOMONTH(J$4,0),OR(INDEX(tblRoster[End Date],$A8)="",INDEX(tblRoster[End Date],$A8)>=J$4)),INDEX(tblRoster[Annual Salary],$A8)/12*(1+Assumptions!$B$3)*IF(MONTH(J$4)>=Assumptions!$B$5,1+Assumptions!$B$4,1),0) -> 9633.9333 | K8: =IF(AND(INDEX(tblRoster[Start Date],$A8)<=EOMONTH(K$4,0),OR(INDEX(tblRoster[End Date],$A8)="",INDEX(tblRoster[End Date],$A8)>=K$4)),INDEX(tblRoster[Annual Salary],$A8)/12*(1+Assumptions!$B$3)*IF(MONTH(K$4)>=Assumptions!$B$5,1+Assumptions!$B$4,1),0) -> 9633.9333 | ... O8: =IF(AND(INDEX(tblRoster[Start Date],$A8)<=EOMONTH(O$4,0),OR(INDEX(tblRoster[End Date],$A8)="",INDEX(tblRoster[End Date],$A8)>=O$4)),INDEX(tblRoster[Annual Salary],$A8)/12*(1+Assumptions!$B$3)*IF(MONTH(O$4)>=Assumptions!$B$5,1+Assumptions!$B$4,1),0) -> 9633.9333 | P8: =SUM(D8:O8) -> 114765.4
A9: 5 | B9: =INDEX(tblRoster[Emp ID],$A9) -> E106 | C9: =INDEX(tblRoster[Department],$A9) -> Marketing | D9: =IF(AND(INDEX(tblRoster[Start Date],$A9)<=EOMONTH(D$4,0),OR(INDEX(tblRoster[End Date],$A9)="",INDEX(tblRoster[End Date],$A9)>=D$4)),INDEX(tblRoster[Annual Salary],$A9)/12*(1+Assumptions!$B$3)*IF(MONTH(D$4)>=Assumptions!$B$5,1+Assumptions!$B$4,1),0) -> 13318.333 | E9: =IF(AND(INDEX(tblRoster[Start Date],$A9)<=EOMONTH(E$4,0),OR(INDEX(tblRoster[End Date],$A9)="",INDEX(tblRoster[End Date],$A9)>=E$4)),INDEX(tblRoster[Annual Salary],$A9)/12*(1+Assumptions!$B$3)*IF(MONTH(E$4)>=Assumptions!$B$5,1+Assumptions!$B$4,1),0) -> 13318.333 | F9: =IF(AND(INDEX(tblRoster[Start Date],$A9)<=EOMONTH(F$4,0),OR(INDEX(tblRoster[End Date],$A9)="",INDEX(tblRoster[End Date],$A9)>=F$4)),INDEX(tblRoster[Annual Salary],$A9)/12*(1+Assumptions!$B$3)*IF(MONTH(F$4)>=Assumptions!$B$5,1+Assumptions!$B$4,1),0) -> 13318.333 | G9: =IF(AND(INDEX(tblRoster[Start Date],$A9)<=EOMONTH(G$4,0),OR(INDEX(tblRoster[End Date],$A9)="",INDEX(tblRoster[End Date],$A9)>=G$4)),INDEX(tblRoster[Annual Salary],$A9)/12*(1+Assumptions!$B$3)*IF(MONTH(G$4)>=Assumptions!$B$5,1+Assumptions!$B$4,1),0) -> 13717.883 | H9: =IF(AND(INDEX(tblRoster[Start Date],$A9)<=EOMONTH(H$4,0),OR(INDEX(tblRoster[End Date],$A9)="",INDEX(tblRoster[End Date],$A9)>=H$4)),INDEX(tblRoster[Annual Salary],$A9)/12*(1+Assumptions!$B$3)*IF(MONTH(H$4)>=Assumptions!$B$5,1+Assumptions!$B$4,1),0) -> 13717.883 | I9: =IF(AND(INDEX(tblRoster[Start Date],$A9)<=EOMONTH(I$4,0),OR(INDEX(tblRoster[End Date],$A9)="",INDEX(tblRoster[End Date],$A9)>=I$4)),INDEX(tblRoster[Annual Salary],$A9)/12*(1+Assumptions!$B$3)*IF(MONTH(I$4)>=Assumptions!$B$5,1+Assumptions!$B$4,1),0) -> 13717.883 | J9: =IF(AND(INDEX(tblRoster[Start Date],$A9)<=EOMONTH(J$4,0),OR(INDEX(tblRoster[End Date],$A9)="",INDEX(tblRoster[End Date],$A9)>=J$4)),INDEX(tblRoster[Annual Salary],$A9)/12*(1+Assumptions!$B$3)*IF(MONTH(J$4)>=Assumptions!$B$5,1+Assumptions!$B$4,1),0) -> 13717.883 | K9: =IF(AND(INDEX(tblRoster[Start Date],$A9)<=EOMONTH(K$4,0),OR(INDEX(tblRoster[End Date],$A9)="",INDEX(tblRoster[End Date],$A9)>=K$4)),INDEX(tblRoster[Annual Salary],$A9)/12*(1+Assumptions!$B$3)*IF(MONTH(K$4)>=Assumptions!$B$5,1+Assumptions!$B$4,1),0) -> 13717.883 | ... O9: =IF(AND(INDEX(tblRoster[Start Date],$A9)<=EOMONTH(O$4,0),OR(INDEX(tblRoster[End Date],$A9)="",INDEX(tblRoster[End Date],$A9)>=O$4)),INDEX(tblRoster[Annual Salary],$A9)/12*(1+Assumptions!$B$3)*IF(MONTH(O$4)>=Assumptions!$B$5,1+Assumptions!$B$4,1),0) -> 13717.883 | P9: =SUM(D9:O9) -> 163415.95
A10: 6 | B10: =INDEX(tblRoster[Emp ID],$A10) -> E107 | C10: =INDEX(tblRoster[Department],$A10) -> Support | D10: =IF(AND(INDEX(tblRoster[Start Date],$A10)<=EOMONTH(D$4,0),OR(INDEX(tblRoster[End Date],$A10)="",INDEX(tblRoster[End Date],$A10)>=D$4)),INDEX(tblRoster[Annual Salary],$A10)/12*(1+Assumptions!$B$3)*IF(MONTH(D$4)>=Assumptions!$B$5,1+Assumptions!$B$4,1),0) -> 8641.6667 | E10: =IF(AND(INDEX(tblRoster[Start Date],$A10)<=EOMONTH(E$4,0),OR(INDEX(tblRoster[End Date],$A10)="",INDEX(tblRoster[End Date],$A10)>=E$4)),INDEX(tblRoster[Annual Salary],$A10)/12*(1+Assumptions!$B$3)*IF(MONTH(E$4)>=Assumptions!$B$5,1+Assumptions!$B$4,1),0) -> 8641.6667 | F10: =IF(AND(INDEX(tblRoster[Start Date],$A10)<=EOMONTH(F$4,0),OR(INDEX(tblRoster[End Date],$A10)="",INDEX(tblRoster[End Date],$A10)>=F$4)),INDEX(tblRoster[Annual Salary],$A10)/12*(1+Assumptions!$B$3)*IF(MONTH(F$4)>=Assumptions!$B$5,1+Assumptions!$B$4,1),0) -> 8641.6667 | G10: =IF(AND(INDEX(tblRoster[Start Date],$A10)<=EOMONTH(G$4,0),OR(INDEX(tblRoster[End Date],$A10)="",INDEX(tblRoster[End Date],$A10)>=G$4)),INDEX(tblRoster[Annual Salary],$A10)/12*(1+Assumptions!$B$3)*IF(MONTH(G$4)>=Assumptions!$B$5,1+Assumptions!$B$4,1),0) -> 8900.9167 | H10: =IF(AND(INDEX(tblRoster[Start Date],$A10)<=EOMONTH(H$4,0),OR(INDEX(tblRoster[End Date],$A10)="",INDEX(tblRoster[End Date],$A10)>=H$4)),INDEX(tblRoster[Annual Salary],$A10)/12*(1+Assumptions!$B$3)*IF(MONTH(H$4)>=Assumptions!$B$5,1+Assumptions!$B$4,1),0) -> 8900.9167 | I10: =IF(AND(INDEX(tblRoster[Start Date],$A10)<=EOMONTH(I$4,0),OR(INDEX(tblRoster[End Date],$A10)="",INDEX(tblRoster[End Date],$A10)>=I$4)),INDEX(tblRoster[Annual Salary],$A10)/12*(1+Assumptions!$B$3)*IF(MONTH(I$4)>=Assumptions!$B$5,1+Assumptions!$B$4,1),0) -> 8900.9167 | J10: =IF(AND(INDEX(tblRoster[Start Date],$A10)<=EOMONTH(J$4,0),OR(INDEX(tblRoster[End Date],$A10)="",INDEX(tblRoster[End Date],$A10)>=J$4)),INDEX(tblRoster[Annual Salary],$A10)/12*(1+Assumptions!$B$3)*IF(MONTH(J$4)>=Assumptions!$B$5,1+Assumptions!$B$4,1),0) -> 8900.9167 | K10: =IF(AND(INDEX(tblRoster[Start Date],$A10)<=EOMONTH(K$4,0),OR(INDEX(tblRoster[End Date],$A10)="",INDEX(tblRoster[End Date],$A10)>=K$4)),INDEX(tblRoster[Annual Salary],$A10)/12*(1+Assumptions!$B$3)*IF(MONTH(K$4)>=Assumptions!$B$5,1+Assumptions!$B$4,1),0) -> 8900.9167 | ... O10: =IF(AND(INDEX(tblRoster[Start Date],$A10)<=EOMONTH(O$4,0),OR(INDEX(tblRoster[End Date],$A10)="",INDEX(tblRoster[End Date],$A10)>=O$4)),INDEX(tblRoster[Annual Salary],$A10)/12*(1+Assumptions!$B$3)*IF(MONTH(O$4)>=Assumptions!$B$5,1+Assumptions!$B$4,1),0) -> 8900.9167 | P10: =SUM(D10:O10) -> 106033.25
A11: 7 | B11: =INDEX(tblRoster[Emp ID],$A11) -> E108 | C11: =INDEX(tblRoster[Department],$A11) -> Sales | D11: =IF(AND(INDEX(tblRoster[Start Date],$A11)<=EOMONTH(D$4,0),OR(INDEX(tblRoster[End Date],$A11)="",INDEX(tblRoster[End Date],$A11)>=D$4)),INDEX(tblRoster[Annual Salary],$A11)/12*(1+Assumptions!$B$3)*IF(MONTH(D$4)>=Assumptions!$B$5,1+Assumptions!$B$4,1),0) -> 8641.6667 | E11: =IF(AND(INDEX(tblRoster[Start Date],$A11)<=EOMONTH(E$4,0),OR(INDEX(tblRoster[End Date],$A11)="",INDEX(tblRoster[End Date],$A11)>=E$4)),INDEX(tblRoster[Annual Salary],$A11)/12*(1+Assumptions!$B$3)*IF(MONTH(E$4)>=Assumptions!$B$5,1+Assumptions!$B$4,1),0) -> 8641.6667 | F11: =IF(AND(INDEX(tblRoster[Start Date],$A11)<=EOMONTH(F$4,0),OR(INDEX(tblRoster[End Date],$A11)="",INDEX(tblRoster[End Date],$A11)>=F$4)),INDEX(tblRoster[Annual Salary],$A11)/12*(1+Assumptions!$B$3)*IF(MONTH(F$4)>=Assumptions!$B$5,1+Assumptions!$B$4,1),0) -> 8641.6667 | G11: =IF(AND(INDEX(tblRoster[Start Date],$A11)<=EOMONTH(G$4,0),OR(INDEX(tblRoster[End Date],$A11)="",INDEX(tblRoster[End Date],$A11)>=G$4)),INDEX(tblRoster[Annual Salary],$A11)/12*(1+Assumptions!$B$3)*IF(MONTH(G$4)>=Assumptions!$B$5,1+Assumptions!$B$4,1),0) -> 8900.9167 | H11: =IF(AND(INDEX(tblRoster[Start Date],$A11)<=EOMONTH(H$4,0),OR(INDEX(tblRoster[End Date],$A11)="",INDEX(tblRoster[End Date],$A11)>=H$4)),INDEX(tblRoster[Annual Salary],$A11)/12*(1+Assumptions!$B$3)*IF(MONTH(H$4)>=Assumptions!$B$5,1+Assumptions!$B$4,1),0) -> 8900.9167 | I11: =IF(AND(INDEX(tblRoster[Start Date],$A11)<=EOMONTH(I$4,0),OR(INDEX(tblRoster[End Date],$A11)="",INDEX(tblRoster[End Date],$A11)>=I$4)),INDEX(tblRoster[Annual Salary],$A11)/12*(1+Assumptions!$B$3)*IF(MONTH(I$4)>=Assumptions!$B$5,1+Assumptions!$B$4,1),0) -> 8900.9167 | J11: =IF(AND(INDEX(tblRoster[Start Date],$A11)<=EOMONTH(J$4,0),OR(INDEX(tblRoster[End Date],$A11)="",INDEX(tblRoster[End Date],$A11)>=J$4)),INDEX(tblRoster[Annual Salary],$A11)/12*(1+Assumptions!$B$3)*IF(MONTH(J$4)>=Assumptions!$B$5,1+Assumptions!$B$4,1),0) -> 8900.9167 | K11: =IF(AND(INDEX(tblRoster[Start Date],$A11)<=EOMONTH(K$4,0),OR(INDEX(tblRoster[End Date],$A11)="",INDEX(tblRoster[End Date],$A11)>=K$4)),INDEX(tblRoster[Annual Salary],$A11)/12*(1+Assumptions!$B$3)*IF(MONTH(K$4)>=Assumptions!$B$5,1+Assumptions!$B$4,1),0) -> 8900.9167 | ... O11: =IF(AND(INDEX(tblRoster[Start Date],$A11)<=EOMONTH(O$4,0),OR(INDEX(tblRoster[End Date],$A11)="",INDEX(tblRoster[End Date],$A11)>=O$4)),INDEX(tblRoster[Annual Salary],$A11)/12*(1+Assumptions!$B$3)*IF(MONTH(O$4)>=Assumptions!$B$5,1+Assumptions!$B$4,1),0) -> 8900.9167 | P11: =SUM(D11:O11) -> 106033.25
A12: 8 | B12: =INDEX(tblRoster[Emp ID],$A12) -> E109 | C12: =INDEX(tblRoster[Department],$A12) -> G&A | D12: =IF(AND(INDEX(tblRoster[Start Date],$A12)<=EOMONTH(D$4,0),OR(INDEX(tblRoster[End Date],$A12)="",INDEX(tblRoster[End Date],$A12)>=D$4)),INDEX(tblRoster[Annual Salary],$A12)/12*(1+Assumptions!$B$3)*IF(MONTH(D$4)>=Assumptions!$B$5,1+Assumptions!$B$4,1),0) -> 8336.6667 | E12: =IF(AND(INDEX(tblRoster[Start Date],$A12)<=EOMONTH(E$4,0),OR(INDEX(tblRoster[End Date],$A12)="",INDEX(tblRoster[End Date],$A12)>=E$4)),INDEX(tblRoster[Annual Salary],$A12)/12*(1+Assumptions!$B$3)*IF(MONTH(E$4)>=Assumptions!$B$5,1+Assumptions!$B$4,1),0) -> 8336.6667 | F12: =IF(AND(INDEX(tblRoster[Start Date],$A12)<=EOMONTH(F$4,0),OR(INDEX(tblRoster[End Date],$A12)="",INDEX(tblRoster[End Date],$A12)>=F$4)),INDEX(tblRoster[Annual Salary],$A12)/12*(1+Assumptions!$B$3)*IF(MONTH(F$4)>=Assumptions!$B$5,1+Assumptions!$B$4,1),0) -> 8336.6667 | G12: =IF(AND(INDEX(tblRoster[Start Date],$A12)<=EOMONTH(G$4,0),OR(INDEX(tblRoster[End Date],$A12)="",INDEX(tblRoster[End Date],$A12)>=G$4)),INDEX(tblRoster[Annual Salary],$A12)/12*(1+Assumptions!$B$3)*IF(MONTH(G$4)>=Assumptions!$B$5,1+Assumptions!$B$4,1),0) -> 8586.7667 | H12: =IF(AND(INDEX(tblRoster[Start Date],$A12)<=EOMONTH(H$4,0),OR(INDEX(tblRoster[End Date],$A12)="",INDEX(tblRoster[End Date],$A12)>=H$4)),INDEX(tblRoster[Annual Salary],$A12)/12*(1+Assumptions!$B$3)*IF(MONTH(H$4)>=Assumptions!$B$5,1+Assumptions!$B$4,1),0) -> 8586.7667 | I12: =IF(AND(INDEX(tblRoster[Start Date],$A12)<=EOMONTH(I$4,0),OR(INDEX(tblRoster[End Date],$A12)="",INDEX(tblRoster[End Date],$A12)>=I$4)),INDEX(tblRoster[Annual Salary],$A12)/12*(1+Assumptions!$B$3)*IF(MONTH(I$4)>=Assumptions!$B$5,1+Assumptions!$B$4,1),0) -> 8586.7667 | J12: =IF(AND(INDEX(tblRoster[Start Date],$A12)<=EOMONTH(J$4,0),OR(INDEX(tblRoster[End Date],$A12)="",INDEX(tblRoster[End Date],$A12)>=J$4)),INDEX(tblRoster[Annual Salary],$A12)/12*(1+Assumptions!$B$3)*IF(MONTH(J$4)>=Assumptions!$B$5,1+Assumptions!$B$4,1),0) -> 8586.7667 | K12: =IF(AND(INDEX(tblRoster[Start Date],$A12)<=EOMONTH(K$4,0),OR(INDEX(tblRoster[End Date],$A12)="",INDEX(tblRoster[End Date],$A12)>=K$4)),INDEX(tblRoster[Annual Salary],$A12)/12*(1+Assumptions!$B$3)*IF(MONTH(K$4)>=Assumptions!$B$5,1+Assumptions!$B$4,1),0) -> 8586.7667 | ... O12: =IF(AND(INDEX(tblRoster[Start Date],$A12)<=EOMONTH(O$4,0),OR(INDEX(tblRoster[End Date],$A12)="",INDEX(tblRoster[End Date],$A12)>=O$4)),INDEX(tblRoster[Annual Salary],$A12)/12*(1+Assumptions!$B$3)*IF(MONTH(O$4)>=Assumptions!$B$5,1+Assumptions!$B$4,1),0) -> 8586.7667 | P12: =SUM(D12:O12) -> 102290.9
A13: 9 | B13: =INDEX(tblRoster[Emp ID],$A13) -> E110 | C13: =INDEX(tblRoster[Department],$A13) -> Engineering | D13: =IF(AND(INDEX(tblRoster[Start Date],$A13)<=EOMONTH(D$4,0),OR(INDEX(tblRoster[End Date],$A13)="",INDEX(tblRoster[End Date],$A13)>=D$4)),INDEX(tblRoster[Annual Salary],$A13)/12*(1+Assumptions!$B$3)*IF(MONTH(D$4)>=Assumptions!$B$5,1+Assumptions!$B$4,1),0) -> 10573.333 | E13: =IF(AND(INDEX(tblRoster[Start Date],$A13)<=EOMONTH(E$4,0),OR(INDEX(tblRoster[End Date],$A13)="",INDEX(tblRoster[End Date],$A13)>=E$4)),INDEX(tblRoster[Annual Salary],$A13)/12*(1+Assumptions!$B$3)*IF(MONTH(E$4)>=Assumptions!$B$5,1+Assumptions!$B$4,1),0) -> 10573.333 | F13: =IF(AND(INDEX(tblRoster[Start Date],$A13)<=EOMONTH(F$4,0),OR(INDEX(tblRoster[End Date],$A13)="",INDEX(tblRoster[End Date],$A13)>=F$4)),INDEX(tblRoster[Annual Salary],$A13)/12*(1+Assumptions!$B$3)*IF(MONTH(F$4)>=Assumptions!$B$5,1+Assumptions!$B$4,1),0) -> 10573.333 | G13: =IF(AND(INDEX(tblRoster[Start Date],$A13)<=EOMONTH(G$4,0),OR(INDEX(tblRoster[End Date],$A13)="",INDEX(tblRoster[End Date],$A13)>=G$4)),INDEX(tblRoster[Annual Salary],$A13)/12*(1+Assumptions!$B$3)*IF(MONTH(G$4)>=Assumptions!$B$5,1+Assumptions!$B$4,1),0) -> 10890.533 | H13: =IF(AND(INDEX(tblRoster[Start Date],$A13)<=EOMONTH(H$4,0),OR(INDEX(tblRoster[End Date],$A13)="",INDEX(tblRoster[End Date],$A13)>=H$4)),INDEX(tblRoster[Annual Salary],$A13)/12*(1+Assumptions!$B$3)*IF(MONTH(H$4)>=Assumptions!$B$5,1+Assumptions!$B$4,1),0) -> 10890.533 | I13: =IF(AND(INDEX(tblRoster[Start Date],$A13)<=EOMONTH(I$4,0),OR(INDEX(tblRoster[End Date],$A13)="",INDEX(tblRoster[End Date],$A13)>=I$4)),INDEX(tblRoster[Annual Salary],$A13)/12*(1+Assumptions!$B$3)*IF(MONTH(I$4)>=Assumptions!$B$5,1+Assumptions!$B$4,1),0) -> 10890.533 | J13: =IF(AND(INDEX(tblRoster[Start Date],$A13)<=EOMONTH(J$4,0),OR(INDEX(tblRoster[End Date],$A13)="",INDEX(tblRoster[End Date],$A13)>=J$4)),INDEX(tblRoster[Annual Salary],$A13)/12*(1+Assumptions!$B$3)*IF(MONTH(J$4)>=Assumptions!$B$5,1+Assumptions!$B$4,1),0) -> 10890.533 | K13: =IF(AND(INDEX(tblRoster[Start Date],$A13)<=EOMONTH(K$4,0),OR(INDEX(tblRoster[End Date],$A13)="",INDEX(tblRoster[End Date],$A13)>=K$4)),INDEX(tblRoster[Annual Salary],$A13)/12*(1+Assumptions!$B$3)*IF(MONTH(K$4)>=Assumptions!$B$5,1+Assumptions!$B$4,1),0) -> 10890.533 | ... O13: =IF(AND(INDEX(tblRoster[Start Date],$A13)<=EOMONTH(O$4,0),OR(INDEX(tblRoster[End Date],$A13)="",INDEX(tblRoster[End Date],$A13)>=O$4)),INDEX(tblRoster[Annual Salary],$A13)/12*(1+Assumptions!$B$3)*IF(MONTH(O$4)>=Assumptions!$B$5,1+Assumptions!$B$4,1),0) -> 10890.533 | P13: =SUM(D13:O13) -> 129734.8
A14: 10 | B14: =INDEX(tblRoster[Emp ID],$A14) -> E111 | C14: =INDEX(tblRoster[Department],$A14) -> Marketing | D14: =IF(AND(INDEX(tblRoster[Start Date],$A14)<=EOMONTH(D$4,0),OR(INDEX(tblRoster[End Date],$A14)="",INDEX(tblRoster[End Date],$A14)>=D$4)),INDEX(tblRoster[Annual Salary],$A14)/12*(1+Assumptions!$B$3)*IF(MONTH(D$4)>=Assumptions!$B$5,1+Assumptions!$B$4,1),0) -> 10166.667 | E14: =IF(AND(INDEX(tblRoster[Start Date],$A14)<=EOMONTH(E$4,0),OR(INDEX(tblRoster[End Date],$A14)="",INDEX(tblRoster[End Date],$A14)>=E$4)),INDEX(tblRoster[Annual Salary],$A14)/12*(1+Assumptions!$B$3)*IF(MONTH(E$4)>=Assumptions!$B$5,1+Assumptions!$B$4,1),0) -> 10166.667 | F14: =IF(AND(INDEX(tblRoster[Start Date],$A14)<=EOMONTH(F$4,0),OR(INDEX(tblRoster[End Date],$A14)="",INDEX(tblRoster[End Date],$A14)>=F$4)),INDEX(tblRoster[Annual Salary],$A14)/12*(1+Assumptions!$B$3)*IF(MONTH(F$4)>=Assumptions!$B$5,1+Assumptions!$B$4,1),0) -> 10166.667 | G14: =IF(AND(INDEX(tblRoster[Start Date],$A14)<=EOMONTH(G$4,0),OR(INDEX(tblRoster[End Date],$A14)="",INDEX(tblRoster[End Date],$A14)>=G$4)),INDEX(tblRoster[Annual Salary],$A14)/12*(1+Assumptions!$B$3)*IF(MONTH(G$4)>=Assumptions!$B$5,1+Assumptions!$B$4,1),0) -> 10471.667 | H14: =IF(AND(INDEX(tblRoster[Start Date],$A14)<=EOMONTH(H$4,0),OR(INDEX(tblRoster[End Date],$A14)="",INDEX(tblRoster[End Date],$A14)>=H$4)),INDEX(tblRoster[Annual Salary],$A14)/12*(1+Assumptions!$B$3)*IF(MONTH(H$4)>=Assumptions!$B$5,1+Assumptions!$B$4,1),0) -> 10471.667 | I14: =IF(AND(INDEX(tblRoster[Start Date],$A14)<=EOMONTH(I$4,0),OR(INDEX(tblRoster[End Date],$A14)="",INDEX(tblRoster[End Date],$A14)>=I$4)),INDEX(tblRoster[Annual Salary],$A14)/12*(1+Assumptions!$B$3)*IF(MONTH(I$4)>=Assumptions!$B$5,1+Assumptions!$B$4,1),0) -> 10471.667 | J14: =IF(AND(INDEX(tblRoster[Start Date],$A14)<=EOMONTH(J$4,0),OR(INDEX(tblRoster[End Date],$A14)="",INDEX(tblRoster[End Date],$A14)>=J$4)),INDEX(tblRoster[Annual Salary],$A14)/12*(1+Assumptions!$B$3)*IF(MONTH(J$4)>=Assumptions!$B$5,1+Assumptions!$B$4,1),0) -> 10471.667 | K14: =IF(AND(INDEX(tblRoster[Start Date],$A14)<=EOMONTH(K$4,0),OR(INDEX(tblRoster[End Date],$A14)="",INDEX(tblRoster[End Date],$A14)>=K$4)),INDEX(tblRoster[Annual Salary],$A14)/12*(1+Assumptions!$B$3)*IF(MONTH(K$4)>=Assumptions!$B$5,1+Assumptions!$B$4,1),0) -> 10471.667 | ... O14: =IF(AND(INDEX(tblRoster[Start Date],$A14)<=EOMONTH(O$4,0),OR(INDEX(tblRoster[End Date],$A14)="",INDEX(tblRoster[End Date],$A14)>=O$4)),INDEX(tblRoster[Annual Salary],$A14)/12*(1+Assumptions!$B$3)*IF(MONTH(O$4)>=Assumptions!$B$5,1+Assumptions!$B$4,1),0) -> 0 | P14: =SUM(D14:O14) -> 93330
A15: 11 | B15: =INDEX(tblRoster[Emp ID],$A15) -> E112 | C15: =INDEX(tblRoster[Department],$A15) -> Support | D15: =IF(AND(INDEX(tblRoster[Start Date],$A15)<=EOMONTH(D$4,0),OR(INDEX(tblRoster[End Date],$A15)="",INDEX(tblRoster[End Date],$A15)>=D$4)),INDEX(tblRoster[Annual Salary],$A15)/12*(1+Assumptions!$B$3)*IF(MONTH(D$4)>=Assumptions!$B$5,1+Assumptions!$B$4,1),0) -> 11793.333 | E15: =IF(AND(INDEX(tblRoster[Start Date],$A15)<=EOMONTH(E$4,0),OR(INDEX(tblRoster[End Date],$A15)="",INDEX(tblRoster[End Date],$A15)>=E$4)),INDEX(tblRoster[Annual Salary],$A15)/12*(1+Assumptions!$B$3)*IF(MONTH(E$4)>=Assumptions!$B$5,1+Assumptions!$B$4,1),0) -> 11793.333 | F15: =IF(AND(INDEX(tblRoster[Start Date],$A15)<=EOMONTH(F$4,0),OR(INDEX(tblRoster[End Date],$A15)="",INDEX(tblRoster[End Date],$A15)>=F$4)),INDEX(tblRoster[Annual Salary],$A15)/12*(1+Assumptions!$B$3)*IF(MONTH(F$4)>=Assumptions!$B$5,1+Assumptions!$B$4,1),0) -> 11793.333 | G15: =IF(AND(INDEX(tblRoster[Start Date],$A15)<=EOMONTH(G$4,0),OR(INDEX(tblRoster[End Date],$A15)="",INDEX(tblRoster[End Date],$A15)>=G$4)),INDEX(tblRoster[Annual Salary],$A15)/12*(1+Assumptions!$B$3)*IF(MONTH(G$4)>=Assumptions!$B$5,1+Assumptions!$B$4,1),0) -> 12147.133 | H15: =IF(AND(INDEX(tblRoster[Start Date],$A15)<=EOMONTH(H$4,0),OR(INDEX(tblRoster[End Date],$A15)="",INDEX(tblRoster[End Date],$A15)>=H$4)),INDEX(tblRoster[Annual Salary],$A15)/12*(1+Assumptions!$B$3)*IF(MONTH(H$4)>=Assumptions!$B$5,1+Assumptions!$B$4,1),0) -> 12147.133 | I15: =IF(AND(INDEX(tblRoster[Start Date],$A15)<=EOMONTH(I$4,0),OR(INDEX(tblRoster[End Date],$A15)="",INDEX(tblRoster[End Date],$A15)>=I$4)),INDEX(tblRoster[Annual Salary],$A15)/12*(1+Assumptions!$B$3)*IF(MONTH(I$4)>=Assumptions!$B$5,1+Assumptions!$B$4,1),0) -> 12147.133 | J15: =IF(AND(INDEX(tblRoster[Start Date],$A15)<=EOMONTH(J$4,0),OR(INDEX(tblRoster[End Date],$A15)="",INDEX(tblRoster[End Date],$A15)>=J$4)),INDEX(tblRoster[Annual Salary],$A15)/12*(1+Assumptions!$B$3)*IF(MONTH(J$4)>=Assumptions!$B$5,1+Assumptions!$B$4,1),0) -> 12147.133 | K15: =IF(AND(INDEX(tblRoster[Start Date],$A15)<=EOMONTH(K$4,0),OR(INDEX(tblRoster[End Date],$A15)="",INDEX(tblRoster[End Date],$A15)>=K$4)),INDEX(tblRoster[Annual Salary],$A15)/12*(1+Assumptions!$B$3)*IF(MONTH(K$4)>=Assumptions!$B$5,1+Assumptions!$B$4,1),0) -> 12147.133 | ... O15: =IF(AND(INDEX(tblRoster[Start Date],$A15)<=EOMONTH(O$4,0),OR(INDEX(tblRoster[End Date],$A15)="",INDEX(tblRoster[End Date],$A15)>=O$4)),INDEX(tblRoster[Annual Salary],$A15)/12*(1+Assumptions!$B$3)*IF(MONTH(O$4)>=Assumptions!$B$5,1+Assumptions!$B$4,1),0) -> 12147.133 | P15: =SUM(D15:O15) -> 144704.2
A16: 12 | B16: =INDEX(tblRoster[Emp ID],$A16) -> E113 | C16: =INDEX(tblRoster[Department],$A16) -> Sales | D16: =IF(AND(INDEX(tblRoster[Start Date],$A16)<=EOMONTH(D$4,0),OR(INDEX(tblRoster[End Date],$A16)="",INDEX(tblRoster[End Date],$A16)>=D$4)),INDEX(tblRoster[Annual Salary],$A16)/12*(1+Assumptions!$B$3)*IF(MONTH(D$4)>=Assumptions!$B$5,1+Assumptions!$B$4,1),0) -> 11996.667 | E16: =IF(AND(INDEX(tblRoster[Start Date],$A16)<=EOMONTH(E$4,0),OR(INDEX(tblRoster[End Date],$A16)="",INDEX(tblRoster[End Date],$A16)>=E$4)),INDEX(tblRoster[Annual Salary],$A16)/12*(1+Assumptions!$B$3)*IF(MONTH(E$4)>=Assumptions!$B$5,1+Assumptions!$B$4,1),0) -> 11996.667 | F16: =IF(AND(INDEX(tblRoster[Start Date],$A16)<=EOMONTH(F$4,0),OR(INDEX(tblRoster[End Date],$A16)="",INDEX(tblRoster[End Date],$A16)>=F$4)),INDEX(tblRoster[Annual Salary],$A16)/12*(1+Assumptions!$B$3)*IF(MONTH(F$4)>=Assumptions!$B$5,1+Assumptions!$B$4,1),0) -> 11996.667 | G16: =IF(AND(INDEX(tblRoster[Start Date],$A16)<=EOMONTH(G$4,0),OR(INDEX(tblRoster[End Date],$A16)="",INDEX(tblRoster[End Date],$A16)>=G$4)),INDEX(tblRoster[Annual Salary],$A16)/12*(1+Assumptions!$B$3)*IF(MONTH(G$4)>=Assumptions!$B$5,1+Assumptions!$B$4,1),0) -> 12356.567 | H16: =IF(AND(INDEX(tblRoster[Start Date],$A16)<=EOMONTH(H$4,0),OR(INDEX(tblRoster[End Date],$A16)="",INDEX(tblRoster[End Date],$A16)>=H$4)),INDEX(tblRoster[Annual Salary],$A16)/12*(1+Assumptions!$B$3)*IF(MONTH(H$4)>=Assumptions!$B$5,1+Assumptions!$B$4,1),0) -> 12356.567 | I16: =IF(AND(INDEX(tblRoster[Start Date],$A16)<=EOMONTH(I$4,0),OR(INDEX(tblRoster[End Date],$A16)="",INDEX(tblRoster[End Date],$A16)>=I$4)),INDEX(tblRoster[Annual Salary],$A16)/12*(1+Assumptions!$B$3)*IF(MONTH(I$4)>=Assumptions!$B$5,1+Assumptions!$B$4,1),0) -> 12356.567 | J16: =IF(AND(INDEX(tblRoster[Start Date],$A16)<=EOMONTH(J$4,0),OR(INDEX(tblRoster[End Date],$A16)="",INDEX(tblRoster[End Date],$A16)>=J$4)),INDEX(tblRoster[Annual Salary],$A16)/12*(1+Assumptions!$B$3)*IF(MONTH(J$4)>=Assumptions!$B$5,1+Assumptions!$B$4,1),0) -> 12356.567 | K16: =IF(AND(INDEX(tblRoster[Start Date],$A16)<=EOMONTH(K$4,0),OR(INDEX(tblRoster[End Date],$A16)="",INDEX(tblRoster[End Date],$A16)>=K$4)),INDEX(tblRoster[Annual Salary],$A16)/12*(1+Assumptions!$B$3)*IF(MONTH(K$4)>=Assumptions!$B$5,1+Assumptions!$B$4,1),0) -> 12356.567 | ... O16: =IF(AND(INDEX(tblRoster[Start Date],$A16)<=EOMONTH(O$4,0),OR(INDEX(tblRoster[End Date],$A16)="",INDEX(tblRoster[End Date],$A16)>=O$4)),INDEX(tblRoster[Annual Salary],$A16)/12*(1+Assumptions!$B$3)*IF(MONTH(O$4)>=Assumptions!$B$5,1+Assumptions!$B$4,1),0) -> 12356.567 | P16: =SUM(D16:O16) -> 147199.1
... A44: 40 | B44: =INDEX(tblRoster[Emp ID],$A44) -> E141 | C44: =INDEX(tblRoster[Department],$A44) -> Marketing | D44: =IF(AND(INDEX(tblRoster[Start Date],$A44)<=EOMONTH(D$4,0),OR(INDEX(tblRoster[End Date],$A44)="",INDEX(tblRoster[End Date],$A44)>=D$4)),INDEX(tblRoster[Annual Salary],$A44)/12*(1+Assumptions!$B$3)*IF(MONTH(D$4)>=Assumptions!$B$5,1+Assumptions!$B$4,1),0) -> 0 | E44: =IF(AND(INDEX(tblRoster[Start Date],$A44)<=EOMONTH(E$4,0),OR(INDEX(tblRoster[End Date],$A44)="",INDEX(tblRoster[End Date],$A44)>=E$4)),INDEX(tblRoster[Annual Salary],$A44)/12*(1+Assumptions!$B$3)*IF(MONTH(E$4)>=Assumptions!$B$5,1+Assumptions!$B$4,1),0) -> 0 | F44: =IF(AND(INDEX(tblRoster[Start Date],$A44)<=EOMONTH(F$4,0),OR(INDEX(tblRoster[End Date],$A44)="",INDEX(tblRoster[End Date],$A44)>=F$4)),INDEX(tblRoster[Annual Salary],$A44)/12*(1+Assumptions!$B$3)*IF(MONTH(F$4)>=Assumptions!$B$5,1+Assumptions!$B$4,1),0) -> 11691.667 | G44: =IF(AND(INDEX(tblRoster[Start Date],$A44)<=EOMONTH(G$4,0),OR(INDEX(tblRoster[End Date],$A44)="",INDEX(tblRoster[End Date],$A44)>=G$4)),INDEX(tblRoster[Annual Salary],$A44)/12*(1+Assumptions!$B$3)*IF(MONTH(G$4)>=Assumptions!$B$5,1+Assumptions!$B$4,1),0) -> 12042.417 | H44: =IF(AND(INDEX(tblRoster[Start Date],$A44)<=EOMONTH(H$4,0),OR(INDEX(tblRoster[End Date],$A44)="",INDEX(tblRoster[End Date],$A44)>=H$4)),INDEX(tblRoster[Annual Salary],$A44)/12*(1+Assumptions!$B$3)*IF(MONTH(H$4)>=Assumptions!$B$5,1+Assumptions!$B$4,1),0) -> 12042.417 | I44: =IF(AND(INDEX(tblRoster[Start Date],$A44)<=EOMONTH(I$4,0),OR(INDEX(tblRoster[End Date],$A44)="",INDEX(tblRoster[End Date],$A44)>=I$4)),INDEX(tblRoster[Annual Salary],$A44)/12*(1+Assumptions!$B$3)*IF(MONTH(I$4)>=Assumptions!$B$5,1+Assumptions!$B$4,1),0) -> 12042.417 | J44: =IF(AND(INDEX(tblRoster[Start Date],$A44)<=EOMONTH(J$4,0),OR(INDEX(tblRoster[End Date],$A44)="",INDEX(tblRoster[End Date],$A44)>=J$4)),INDEX(tblRoster[Annual Salary],$A44)/12*(1+Assumptions!$B$3)*IF(MONTH(J$4)>=Assumptions!$B$5,1+Assumptions!$B$4,1),0) -> 12042.417 | K44: =IF(AND(INDEX(tblRoster[Start Date],$A44)<=EOMONTH(K$4,0),OR(INDEX(tblRoster[End Date],$A44)="",INDEX(tblRoster[End Date],$A44)>=K$4)),INDEX(tblRoster[Annual Salary],$A44)/12*(1+Assumptions!$B$3)*IF(MONTH(K$4)>=Assumptions!$B$5,1+Assumptions!$B$4,1),0) -> 12042.417 | ... O44: =IF(AND(INDEX(tblRoster[Start Date],$A44)<=EOMONTH(O$4,0),OR(INDEX(tblRoster[End Date],$A44)="",INDEX(tblRoster[End Date],$A44)>=O$4)),INDEX(tblRoster[Annual Salary],$A44)/12*(1+Assumptions!$B$3)*IF(MONTH(O$4)>=Assumptions!$B$5,1+Assumptions!$B$4,1),0) -> 12042.417 | P44: =SUM(D44:O44) -> 120073.42

Sheet Dept Budget
A1: Department | B1: Jan | C1: Feb | D1: Mar | E1: Apr | F1: May | G1: Jun | H1: Jul | I1: Aug | J1: Sep | K1: Oct | L1: Nov | M1: Dec
A2: Engineering | B2: 85000 | C2: 85000 | D2: 88000 | E2: 92000 | F2: 88000 | G2: 85000 | H2: 90000 | I2: 123000 | J2: 127000 | K2: 133000 | L2: 129000 | M2: 126000
A3: Sales | B3: 89000 | C3: 89000 | D3: 82000 | E3: 94000 | F3: 93000 | G3: 80000 | H3: 79000 | I3: 90000 | J3: 90000 | K3: 87000 | L3: 93000 | M3: 86000
A4: Marketing | B4: 89000 | C4: 90000 | D4: 101000 | E4: 126000 | F4: 121000 | G4: 120000 | H4: 123000 | I4: 122000 | J4: 126000 | K4: 111000 | L4: 123000 | M4: 119000
A5: G&A | B5: 57000 | C5: 58000 | D5: 59000 | E5: 74000 | F5: 72000 | G5: 79000 | H5: 81000 | I5: 92000 | J5: 93000 | K5: 88000 | L5: 88000 | M5: 91000
A6: Support | B6: 94000 | C6: 101000 | D6: 92000 | E6: 93000 | F6: 105000 | G6: 100000 | H6: 95000 | I6: 100000 | J6: 93000 | K6: 96000 | L6: 101000 | M6: 100000

Sheet Variance
A1: Plan vs Budget by Department
A3: Department | B3: FY26 Plan | C3: FY26 Budget | D3: Variance | E3: Var % | F3: Dec Headcount
A4: Engineering | B4: =SUMIFS('Monthly Cost'!$P:$P,'Monthly Cost'!$C:$C,$A4) -> 1237257.9 | C4: =SUM(INDEX(tblDeptBudget[[Jan]:[Dec]],MATCH($A4,tblDeptBudget[Department],0),0)) -> 1251000 | D4: =C4-B4 -> 13742.083 | E4: =IFERROR(D4/C4,0) -> 0.010984879 | F4: =COUNTIFS('Monthly Cost'!$C:$C,$A4,'Monthly Cost'!$O:$O,">0") -> 8
A5: Sales | B5: =SUMIFS('Monthly Cost'!$P:$P,'Monthly Cost'!$C:$C,$A5) -> 1036293.4 | C5: =SUM(INDEX(tblDeptBudget[[Jan]:[Dec]],MATCH($A5,tblDeptBudget[Department],0),0)) -> 1052000 | D5: =C5-B5 -> 15706.583 | E5: =IFERROR(D5/C5,0) -> 0.014930212 | F5: =COUNTIFS('Monthly Cost'!$C:$C,$A5,'Monthly Cost'!$O:$O,">0") -> 7
A6: Marketing | B6: =SUMIFS('Monthly Cost'!$P:$P,'Monthly Cost'!$C:$C,$A6) -> 1394753.8 | C6: =SUM(INDEX(tblDeptBudget[[Jan]:[Dec]],MATCH($A6,tblDeptBudget[Department],0),0)) -> 1371000 | D6: =C6-B6 -> -23753.817 | E6: =IFERROR(D6/C6,0) -> -0.017325906 | F6: =COUNTIFS('Monthly Cost'!$C:$C,$A6,'Monthly Cost'!$O:$O,">0") -> 7
A7: G&A | B7: =SUMIFS('Monthly Cost'!$P:$P,'Monthly Cost'!$C:$C,$A7) -> 933163.77 | C7: =SUM(INDEX(tblDeptBudget[[Jan]:[Dec]],MATCH($A7,tblDeptBudget[Department],0),0)) -> 932000 | D7: =C7-B7 -> -1163.7667 | E7: =IFERROR(D7/C7,0) -> -0.0012486767 | F7: =COUNTIFS('Monthly Cost'!$C:$C,$A7,'Monthly Cost'!$O:$O,">0") -> 8
A8: Support | B8: =SUMIFS('Monthly Cost'!$P:$P,'Monthly Cost'!$C:$C,$A8) -> 1155056.4 | C8: =SUM(INDEX(tblDeptBudget[[Jan]:[Dec]],MATCH($A8,tblDeptBudget[Department],0),0)) -> 1170000 | D8: =C8-B8 -> 14943.65 | E8: =IFERROR(D8/C8,0) -> 0.01277235 | F8: =COUNTIFS('Monthly Cost'!$C:$C,$A8,'Monthly Cost'!$O:$O,">0") -> 7
